<!-- =================================================================
     Pupper Model - Final Version with Global PD(Kp, Kv) Settings
     ================================================================= -->
<mujoco model="pupper_global_pd">
  <compiler angle="radian" meshdir="assets" autolimits="true"/>
  <option iterations="1" ls_iterations="5" timestep="0.004" integrator="Euler">
    <flag eulerdamp="disable"/>
  </option>
  <custom>
    <numeric data="30" name="max_contact_points"/>
    <numeric data="12" name="max_geom_pairs"/>
  </custom>

  <!-- [MODIFIED] All physical and control parameters are now globally defined here -->
  <default>
    <default class="pupper">
      <!-- 1. Global physical properties for ALL joints -->
      <joint armature="0.005" damping="0.1" frictionloss="0.2"/>
      
      <!-- 2. Global controller template for ALL position actuators -->
      <!--    kp and kv are placeholders to be modified by the Python script -->
      <general gainprm="0.333" ctrlrange="-5.0 5.0" gear="1" biastype="none"/>


      <!-- Joint-specific kinematics -->
      <default class="abduction">
        <joint axis="0 1 0" range="-1.0472 1.0472"/>
      </default>
      <default class="hip">
        <joint axis="1 0 0" range="-0.76166 3.81442"/>
      </default>
      <default class="knee">
        <joint axis="1 0 0" range="-0.78540 1.65806"/>
      </default>
      
      <!-- Visual and collision definitions -->
      <default class="visual"> <geom type="mesh" contype="0" conaffinity="0" group="2"/> </default>
      <default class="collision"> <geom group="3"/>
        <default class="foot"> <geom type="sphere" size="0.009525" solimp="0.9 .95 0.01" condim="3" friction="0.8 0.1 0.1"/> </default>
      </default>
    </default>
  </default>

  <!-- Assets and Worldbody remain the same -->
  <asset>
    <mesh name="body" file="body.stl" scale="0.001 0.001 0.001"/>
    <mesh name="Hip_L" file="Hip_L.stl" scale="0.001 0.001 0.001"/>
    <mesh name="Hip_R" file="Hip_R.stl" scale="0.001 0.001 0.001"/>
    <mesh name="Upper_Leg_L" file="Upper_Leg_L.stl" scale="0.001 0.001 0.001"/>
    <mesh name="Upper_Leg_R" file="Upper_Leg_R.stl" scale="0.001 0.001 0.001"/>
    <mesh name="Lower_Leg_L" file="Lower_Leg_L.stl" scale="0.001 0.001 0.001"/>
    <mesh name="Lower_Leg_R" file="Lower_Leg_R.stl" scale="0.001 0.001 0.001"/>
  </asset>

  <worldbody>
    <light name="spotlight" mode="targetbodycom" target="torso" pos="3 0 4"/>
    <body name="torso" pos="0 0 0.2" childclass="pupper">
      <camera name="track" pos="0.8 -1.0 0.5" xyaxes="0.707 0.707 0 -0.354 0.354 0.866" mode="trackcom"/>
      <site name="head" pos="0.15 0 0" rgba="1 0 0 1" size="0.02" group="5"/>
      <inertial pos="0 -0.048 -0.00964" mass="0.991" fullinertia="0.00626 0.00175 0.00678 2e-05 0 2e-05" />
      <freejoint/>
      <geom class="visual" mesh="body"/>
      <geom class="collision" type="box" size="0.06 0.11 0.03" pos="0 -0.07 0"/>
      <site name="imu" pos="0 -0.122542 0" size="0.01" group="5"/>
      <body name="FR_hip" pos="-0.046891 -0.203946 -0.0064">
        <inertial pos="0.0139 -0.0269 0" mass="0.106" diaginertia="2e-05 6e-05 6e-05" />
        <joint class="abduction" name="FR_hip_joint"/>
        <geom class="visual" mesh="Hip_R"/>
        <body name="FR_thigh" pos="-0.037 0.028 0" axisangle="1 0 0 0.7854">
          <inertial pos="0.0172 0 -0.061" mass="0.142" diaginertia="0.00014 0.00016 3e-05" />
          <joint class="hip" name="FR_thigh_joint"/>
          <geom class="visual" mesh="Upper_Leg_R"/>
          <body name="FR_calf" pos="0 0 -0.08" axisangle="1 0 0 -1.57">
            <inertial pos="-0.00588 -0.00075 -0.0658" mass="0.038" diaginertia="0.00018 0.00018 2e-05" />
            <joint class="knee" name="FR_calf_joint"/>
            <geom class="visual" mesh="Lower_Leg_R"/>
            <geom name="FR" class="foot" pos="0.003475 0 -0.11"/>
            <site name="FR" pos="0.003475 0 -0.11" type="sphere" size="0.009525" group="5"/>
          </body>
        </body>
      </body>
      <body name="FL_hip" pos="0.047109 -0.203946 -0.0064">
        <inertial pos="0.0139 0.0254 0" mass="0.106" diaginertia="2e-05 6e-05 6e-05" />
        <joint class="abduction" name="FL_hip_joint"/>
        <geom class="visual" mesh="Hip_L"/>
        <body name="FL_thigh" pos="0.037 0.028 0" axisangle="1 0 0 0.7854">
          <inertial pos="0.0172 0 -0.061" mass="0.142" diaginertia="0.00014 0.00016 3e-05" />
          <joint class="hip" name="FL_thigh_joint"/>
          <geom class="visual" mesh="Upper_Leg_L"/>
          <body name="FL_calf" pos="0 0 -0.08" axisangle="1 0 0 -1.57">
            <inertial pos="0.00558 -0.00075 -0.0658" mass="0.038" diaginertia="0.00018 0.00018 2e-05" />
            <joint class="knee" name="FL_calf_joint"/>
            <geom class="visual" mesh="Lower_Leg_L"/>
            <geom name="FL" class="foot" pos="-0.003475 0 -0.11"/>
            <site name="FL" pos="-0.003475 0 -0.11" type="sphere" size="0.009525" group="5"/>
          </body>
        </body>
      </body>
      <body name="RR_hip" pos="-0.046896 -0.004096 -0.0064">
        <inertial pos="0.0139 -0.0269 0" mass="0.106" diaginertia="2e-05 6e-05 6e-05" />
        <joint class="abduction" name="RR_hip_joint"/>
        <geom class="visual" mesh="Hip_R"/>
        <body name="RR_thigh" pos="-0.037 0.028 0" axisangle="1 0 0 0.7854">
          <inertial pos="0.0172 0 -0.061" mass="0.142" diaginertia="0.00014 0.00016 3e-05" />
          <joint class="hip" name="RR_thigh_joint"/>
          <geom class="visual" mesh="Upper_Leg_R"/>
          <body name="RR_calf" pos="0 0 -0.08" axisangle="1 0 0 -1.57">
            <inertial pos="-0.00588 -0.00075 -0.0658" mass="0.038" diaginertia="0.00018 0.00018 2e-05" />
            <joint class="knee" name="RR_calf_joint"/>
            <geom class="visual" mesh="Lower_Leg_R"/>
            <geom name="RR" class="foot" pos="0.003475 0 -0.11"/>
            <site name="RR" pos="0.003475 0 -0.11" type="sphere" size="0.009525" group="5"/>
          </body>
        </body>
      </body>
      <body name="RL_hip" pos="0.047104 -0.004096 -0.0064">
        <inertial pos="0.0139 0.0254 0" mass="0.106" diaginertia="2e-05 6e-05 6e-05" />
        <joint class="abduction" name="RL_hip_joint"/>
        <geom class="visual" mesh="Hip_L"/>
        <body name="RL_thigh" pos="0.037 0.028 0" axisangle="1 0 0 0.7854">
          <inertial pos="0.0172 0 -0.061" mass="0.142" diaginertia="0.00014 0.00016 3e-05" />
          <joint class="hip" name="RL_thigh_joint"/>
          <geom class="visual" mesh="Upper_Leg_L"/>
          <body name="RL_calf" pos="0 0 -0.08" axisangle="1 0 0 -1.57">
            <inertial pos="0.00558 -0.00075 -0.0658" mass="0.038" diaginertia="0.00018 0.00018 2e-05" />
            <joint class="knee" name="RL_calf_joint"/>
            <geom class="visual" mesh="Lower_Leg_L"/>
            <geom name="RL" class="foot" pos="-0.003475 0 -0.11"/>
            <site name="RL" pos="-0.003475 0 -0.11" type="sphere" size="0.009525" group="5"/>
          </body>
        </body>
      </body>
    </body>
  </worldbody>

  <actuator>
      <general name="FR_hip"   joint="FR_hip_joint"/>
      <general name="FR_thigh" joint="FR_thigh_joint"/>
      <general name="FR_calf"  joint="FR_calf_joint"/>
      <general name="FL_hip"   joint="FL_hip_joint"/>
      <general name="FL_thigh" joint="FL_thigh_joint"/>
      <general name="FL_calf"  joint="FL_calf_joint"/>
      <general name="RR_hip"   joint="RR_hip_joint"/>
      <general name="RR_thigh" joint="RR_thigh_joint"/>
      <general name="RR_calf"  joint="RR_calf_joint"/>
      <general name="RL_hip"   joint="RL_hip_joint"/>
      <general name="RL_thigh" joint="RL_thigh_joint"/>
      <general name="RL_calf"  joint="RL_calf_joint"/>
  </actuator>

  <!-- Sensors remain the same -->
  <sensor>
    <gyro site="imu" name="gyro"/>
    <velocimeter site="imu" name="local_linvel"/>
    <accelerometer site="imu" name="accelerometer"/>
    <framepos objtype="site" objname="imu" name="position"/>
    <framezaxis objtype="site" objname="imu" name="upvector"/>
    <framexaxis objtype="site" objname="imu" name="forwardvector"/>
    <framelinvel objtype="site" objname="imu" name="global_linvel"/>
    <frameangvel objtype="site" objname="imu" name="global_angvel"/>
    <framequat objtype="site" objname="imu" name="orientation"/>
    <framelinvel objtype="site" objname="FR" name="FR_global_linvel"/>
    <framelinvel objtype="site" objname="FL" name="FL_global_linvel"/>
    <framelinvel objtype="site" objname="RR" name="RR_global_linvel"/>
    <framelinvel objtype="site" objname="RL" name="RL_global_linvel"/>
    <framepos objtype="site" objname="FR" name="FR_pos" reftype="site" refname="imu"/>
    <framepos objtype="site" objname="FL" name="FL_pos" reftype="site" refname="imu"/>
    <framepos objtype="site" objname="RR" name="RR_pos" reftype="site" refname="imu"/>
    <framepos objtype="site" objname="RL" name="RL_pos" reftype="site" refname="imu"/>
    <framepos objtype="site" objname="head" name="head_pos"/>
  </sensor>
</mujoco>